Workbook

Sheet INTRO
A1: TATA MOTORS DCF VALUATION
I15: Company | J15: Tata Motors Limited
I16: Ticker | J16: #VALUE!
I17: Exchange | J17: NSE
I18: Industry | J18: Automobile & Commercial Vehicles
I19: Currency | J19: INR
I20: Market Cap
I21: Enterprise Value
I22: Current Share Price | J22: {=_FV(J16,"High")} -> 458.35
I23: Intrinsic Value
I24: Upside / Downside
I25: Recommendation
I28: Valuation Date | J28: 46229
I29: Last Updated | J29: =TODAY() -> 46274
I30: Analyst | J30: Shubh Raaj Chopra

Sheet RAW DATA
A1: Metric | B1: FY2021 | C1: FY2022 | D1: FY2023 | E1: FY2024 | F1: FY2025 | G1: FY2026E–FY2030E
A2: Revenue | B2: ✓ | C2: ✓ | D2: ✓ | E2: ✓ | F2: ✓ | G2: ✓
A3: Revenue Growth | B3: ✓ | C3: ✓ | D3: ✓ | E3: ✓ | F3: ✓ | G3: ✓
A4: EBIT | B4: ✓ | C4: ✓ | D4: ✓ | E4: ✓ | F4: ✓ | G4: ✓
A5: EBIT Margin | B5: ✓ | C5: ✓ | D5: ✓ | E5: ✓ | F5: ✓ | G5: ✓
A6: Less: Tax | B6: ✓ | C6: ✓ | D6: ✓ | E6: ✓ | F6: ✓ | G6: ✓
A7: NOPAT | B7: ✓ | C7: ✓ | D7: ✓ | E7: ✓ | F7: ✓ | G7: ✓
A8: D&A | B8: ✓ | C8: ✓ | D8: ✓ | E8: ✓ | F8: ✓ | G8: ✓
A9: Change in Working Capital | B9: ✓ | C9: ✓ | D9: ✓ | E9: ✓ | F9: ✓ | G9: ✓
A10: CAPEX | B10: ✓ | C10: ✓ | D10: ✓ | E10: ✓ | F10: ✓ | G10: ✓
A11: FCFF | B11: ✓ | C11: ✓ | D11: ✓ | E11: ✓ | F11: ✓ | G11: ✓
A23: Particulars | B23: FY2021 | C23: FY2022 | D23: FY2023 | E23: FY2024 | F23: FY2025 | G23: FY2026E | H23: FY2027E | I23: FY2028E | J23: FY2029E | K23: FY2030E
A24: Revenue | B24: 249794.75 | C24: 278453.62 | D24: 345966.97 | E24: 434016 | F24: 439695 | G24: 470473.65 | H24: 503406.81 | I24: 543679.35 | J24: 576300.11 | K24: 605115.12
A25: Revenue Growth | C25: 0.11472967 | D25: 0.24245815 | E25: 0.25450126 | F25: 0.013084771 | G25: 0.07 | H25: 0.07 | I25: 0.08 | J25: 0.06 | K25: 0.05
A26: EBIT | B26: 3286.74 | C26: -6373.83 | D26: 1467.02 | E26: 28668 | F26: 34043 | G26: 36426.01 | H26: 38975.831 | I26: 42093.897 | J26: 45040.47 | K26: 48193.303
A27: EBIT Margin | B27: 0.013157763 | C27: -0.022890096 | D27: 0.004240347 | E27: 0.066052864 | F27: 0.077424124 | G27: 0.07 | H27: 0.07 | I27: 0.08 | J27: 0.07 | K27: 0.07
A28: Less: Tax | B28: 997.81295 | C28: -1935.0147 | D28: 445.36883 | E28: 8703.2445 | F28: 10335.027 | G28: 10927.803 | H28: 11692.749 | I28: 12628.169 | J28: 13512.141 | K28: 14457.991
A29: NOPAT | B29: 2288.927 | C29: -4438.8153 | D29: 1021.6512 | E29: 19964.756 | F29: 23707.973 | G29: 25498.207 | H29: 27283.081 | I29: 29465.728 | J29: 31528.329 | K29: 33735.312
A30: Add: D&A | B30: 23546.71 | C30: 24835.69 | D30: 24860.36 | E30: 27239 | F30: 23256 | G30: 28228.419 | H30: 35238.476 | I30: 38057.554 | J30: 34578.007 | K30: 30255.756
A31: Add/Less: Change in Working Capital | B31: 0 | C31: 5297.63 | D31: 604.25 | E31: 5669.56 | F31: -6983 | G31: 4704.7365 | H31: 5034.0681 | I31: 0 | J31: 5763.0011 | K31: 6051.1512
A32: Less: CAPEX | B32: 18147.21 | C32: 21841.92 | D32: 15067.19 | E32: 22960 | F32: 23822 | G32: 23523.683 | H32: 25170.34 | I32: 32620.761 | J32: 34578.007 | K32: 36306.907
A33: FCFF | B33: 7688.427 | C33: -6742.6753 | D33: 10210.571 | E33: 18574.196 | F33: 30124.973 | G33: 25498.207 | H33: 32317.15 | I33: 34902.522 | J33: 25765.328 | K33: 21633.01
A34: Period | G34: 1 | H34: 2 | I34: 3 | J34: 4 | K34: 5
A35: Discounting Factor | G35: 0.8883389 | H35: 0.78914601 | I35: 0.7010291 | J35: 0.62275142 | K35: 0.55321432
A36: PV of FCFF | G36: 22651.049 | H36: 25502.95 | I36: 24467.683 | J36: 16045.395 | K36: 11967.691
G37: 100634.77
E39: FY2026E | F39: FY2027E | G39: FY2028E | H39: FY2029E | I39: FY2030E
D40: Revenue | E40: 0.07 | F40: 0.07 | G40: 0.08 | H40: 0.06 | I40: 0.05
D43: EBIT | E43: 0.07 | F43: 0.07 | G43: 0.08 | H43: 0.07 | I43: 0.07
D46: TAX | E46: 0.3 | F46: 0.3 | G46: 0.3 | H46: 0.3 | I46: 0.3
A47: Scenario: | B47: 1 = Bear
B48: 2 = Base
B49: 3 = Bull | D49: D&A | E49: 0.06 | F49: 0.07 | G49: 0.07 | H49: 0.06 | I49: 0.05
D52: WC | E52: 0.01 | F52: 0.01 | G52: 0 | H52: 0.01 | I52: 0.01
D55: CAPEX | E55: 0.05 | F55: 0.05 | G55: 0.06 | H55: 0.06 | I55: 0.06
A62: Particulars | B62: Note | C62: FY2021 | D62: FY2022 | E62: FY2023 | F62: FY2024 | G62: FY2025
A63: (a) Revenue | B63: 34 | C63: 246972.17 | D63: 275235.23 | E63: 342874.59 | F63: 431212 | G63: 436821
A64: (b) Other operating revenues | B64: 34 | C64: 2822.58 | D64: 3218.39 | E64: 3092.38 | F64: 2804 | G64: 2874
A65: I. Total revenue from operations | B65: 34 | C65: =SUM(C63:C64) -> 249794.75 | D65: =SUM(D63:D64) -> 278453.62 | E65: =SUM(E63:E64) -> 345966.97 | F65: =SUM(F63:F64) -> 434016 | G65: =SUM(G63:G64) -> 439695
A66: II. Other income | B66: 35 | C66: 2643.19 | D66: 3053.63 | E66: 4633.18 | F66: 5692 | G66: 6244
...

Sheet DASHBOARD
A1: TATA MOTORS — DCF & FINANCIAL DASHBOARD
B10: ='DCF Dashboard'!Q4 -> 439695 | E10: ='DCF Dashboard'!Q6 -> 34043 | H10: ='DCF Dashboard'!F17 -> 79025.359 | L10: ='DCF Dashboard'!Q9 -> 23707.973
A19: Revenue Vs Revenue Growth | O19: Revenue From Operations | AD19: Gross Debt Distibution
A56: FCFF | O56: Net Debt By EBITDA | W56: Assumptions %

Sheet Consolidated Income Statement
A1: Particulars | B1: Note | C1: FY2021 | D1: FY2022 | E1: FY2023 | F1: FY2024 | G1: FY2025 | H1: FY2026 | I1: FY2027 | J1: FY2028 | K1: FY2029 | L1: FY2030
A2: (a) Revenue | B2: 34 | C2: 246972.17 | D2: 275235.23 | E2: 342874.59 | F2: 431212 | G2: 436821
A3: (b) Other operating revenues | B3: 34 | C3: 2822.58 | D3: 3218.39 | E3: 3092.38 | F3: 2804 | G3: 2874
A4: I. Total revenue from operations | B4: 34 | C4: =SUM(C2:C3) -> 249794.75 | D4: =SUM(D2:D3) -> 278453.62 | E4: =SUM(E2:E3) -> 345966.97 | F4: =SUM(F2:F3) -> 434016 | G4: =SUM(G2:G3) -> 439695
A5: II. Other income | B5: 35 | C5: 2643.19 | D5: 3053.63 | E5: 4633.18 | F5: 5692 | G5: 6244
A6: III. Total Income (I+II) | C6: =SUM(C4:C5) -> 252437.94 | D6: =SUM(D4:D5) -> 281507.25 | E6: =SUM(E4:E5) -> 350600.15 | F6: =SUM(F4:F5) -> 439708 | G6: =SUM(G4:G5) -> 445939
A7: IV. Expenses:
A8: (a)(i) Cost of materials consumed | C8: 141392.43 | D8: 159598.06 | E8: 208218.05 | F8: 249278 | G8: 241148
A9: (a)(ii) Basis adjustment on hedge accounted derivatives | C9: -35.16 | D9: 1322.5 | E9: 726.26 | F9: - | G9: -
A10: (b) Purchase of products for sale | C10: 12250.09 | D10: 18374.77 | E10: 22306.95 | F10: 25043 | G10: 27802
A11: (c) Changes in inventories of finished goods, work-in-progress and products for sale | C11: 4684.16 | D11: 1590.49 | E11: -4781.62 | F11: -1566 | G11: 2836
A12: (d) Employee benefits expense | B12: 36 | C12: 27648.48 | D12: 30808.52 | E12: 33654.7 | F12: 41990 | G12: 47767
A13: (e) Finance costs | B13: 37 | C13: 8097.17 | D13: 9311.86 | E13: 10225.48 | F13: 7594 | G13: 5083
A14: (f) Compulsorily convertible preference share measured at fair value (gain)/loss | C14: - | D14: 14.45 | E14: 13.75 | F14: 48 | G14: -84
A15: (g) Foreign exchange (gain)/loss (net) | C15: -1732.15 | D15: 78.68 | E15: -103.88 | F15: 15 | G15: -922
A16: (h) Depreciation and amortisation expense | C16: 23546.71 | D16: 24835.69 | E16: 24860.36 | F16: 27239 | G16: 23256
A17: (i) Product development/engineering expenses | B17: 38(ii) | C17: 5226.63 | D17: 9209.5 | E17: 10661.96 | F17: 10959 | G17: 10716
A18: (j) Other expenses | B18: 39 | C18: 40921.97 | D18: 47133.85 | E18: 61785.96 | F18: 77198 | G18: 85399
A19: (k) Amount transferred to capital and other account | B19: 38(i) | C19: -12849.13 | D19: -14397.29 | E19: -18434.84 | F19: -26758 | G19: -31105
A20: Total Expenses (IV) | C20: =SUM(C8:C19) -> 249151.2 | D20: =SUM(D8:D19) -> 287881.08 | E20: =SUM(E8:E19) -> 349133.13 | F20: =SUM(F8:F19) -> 411040 | G20: =SUM(G8:G19) -> 411896
A21: V. Profit/(loss) before exceptional items and tax (III-IV) | C21: =C6-C20 -> 3286.74 | D21: =D6-D20 -> -6373.83 | E21: =E6-E20 -> 1467.02 | F21: =F6-F20 -> 28668 | G21: =G6-G20 -> 34043
C22: - | D22: -
A24: Exceptional items - Defined benefit pension plan amendment past service cost/(credit) | C24: 84.81 | D24: - | E24: -1495.07 | F24: - | G24: -
A25: Exceptional items - Employee separation cost | C25: 459.9 | D25: 9.83 | E25: 1.45 | F25: - | G25: -
A26: Exceptional items - Restructuring cost at JLR / Charge associated with change in JLR Strategy | C26: 14994.3 | D26: - | E26: - | F26: - | G26: -
A27: Exceptional items - Write off/provision for tangible/intangible assets (including under development) (net) | C27: 114 | D27: - | E27: 229.96 | F27: - | G27: -
A28: Exceptional items - Reversal for onerous contracts and related supplier claims | C28: -663 | D28: - | E28: -61.03 | F28: - | G28: -
A29: Exceptional items - Reversal of Impairment/(Impairment) in Passenger Vehicle Business | B29: 8(a) | C29: -1182.41 | D29: - | E29: - | F29: - | G29: -
A30: Exceptional items - Reversal for cost of closure of operation of a subsidiary | C30: -46.58 | D30: -21.47 | E30: - | F30: - | G30: -
A31: Exceptional items - Reversal of Impairment in subsidiaries | B31: 8(c) | C31: - | D31: -86.26 | E31: -214.39 | F31: - | G31: -
A32: Exceptional items - Cost of slump sale of passenger vehicle undertaking | C32: - | D32: 301.34 | E32: 9 | F32: - | G32: -
A33: Exceptional items - Provision for Russia market | B33: 49(e) | C33: - | D33: 428.66 | E33: - | F33: - | G33: -
A34: Exceptional items - Others / Other exceptional items | B34: 49(c) | C34: - | D34: -2.52 | E34: -60.45 | F34: - | G34: -
A35: Exceptional items - Impairment in subsidiaries | C35: 353.2 | D35: - | E35: - | F35: - | G35: -
A36: Exceptional items - Provision for loan given to a Joint venture | C36: 25.12 | D36: - | E36: - | F36: - | G36: -
A37: VIII. Exceptional items [loss]/gain (net) - Total | B37: 40 | C37: 13761.02 | D37: =SUM(D24:D36) -> 629.58 | E37: =SUM(E24:E36) -> -1590.53 | F37: 939 | G37: 550
A38: IX. Profit before tax from continuing operations (VII-VIII) [FY25/24] | C38: -10474.28 | D38: -7003.41 | E38: 3057.55 | F38: =F37+F21 -> 29607 | G38: =G37+G21 -> 34593
F39: -
A40: Current tax (including Minimum Alternate Tax) | C40: 1710.18 | D40: 2669.98 | E40: 3258.35 | F40: 4937 | G40: 5023
A41: Deferred tax | C41: 831.68 | D41: 1561.31 | E41: -2554.29 | F41: -8961 | G41: 5479
...

Sheet DCF Dashboard
A1: DISCOUNTED CASHFLOW VALUATION METHOD | L1: Forecast
A2: (in CR) | AA2: Revenue | AB2: FY2026E | AC2: FY2027E | AD2: FY2028E | AE2: FY2029E | AF2: FY2030E
A3: Particulars | F3: 1 | G3: =F3+1 -> 2 | H3: =G3+1 -> 3 | I3: =H3+1 -> 4 | J3: =I3+1 -> 5 | L3: Particulars | M3: FY2021 | N3: FY2022 | O3: FY2023 | P3: FY2024 | Q3: FY2025 | R3: FY2026E | S3: FY2027E | T3: FY2028E | U3: FY2029E | V3: FY2030E | AB3: 0.07 | AC3: 0.07 | AD3: 0.08 | AE3: 0.07 | AF3: 0.06
F4: FY2021 | G4: FY2022 | H4: FY2023 | I4: FY2024 | J4: FY2025 | L4: Revenue | M4: ='Consolidated Income Statement'!C4 -> 249794.75 | N4: ='Consolidated Income Statement'!D4 -> 278453.62 | O4: ='Consolidated Income Statement'!E4 -> 345966.97 | P4: ='Consolidated Income Statement'!F4 -> 434016 | Q4: ='Consolidated Income Statement'!G4 -> 439695 | R4: =Q4*(1+AB$3) -> 470473.65 | S4: =R4*(1+AC$3) -> 503406.81 | T4: =S4*(1+AD$3) -> 543679.35 | U4: =T4*(1+AE$3) -> 581736.9 | V4: =U4*(1+AF$3) -> 616641.12
A5: EBIT | F5: ='Consolidated Income Statement'!C21 -> 3286.74 | G5: ='Consolidated Income Statement'!D21 -> -6373.83 | H5: ='Consolidated Income Statement'!E21 -> 1467.02 | I5: ='Consolidated Income Statement'!F21 -> 28668 | J5: ='Consolidated Income Statement'!G21 -> 34043 | L5: Revenue Growth | N5: =(N4-M4)/M4 -> 0.11472967 | O5: =(O4-N4)/N4 -> 0.24245815 | P5: =(P4-O4)/O4 -> 0.25450126 | Q5: =(Q4-P4)/P4 -> 0.013084771 | R5: =(R4-Q4)/Q4 -> 0.07 | S5: =(S4-R4)/R4 -> 0.07 | T5: =(T4-S4)/S4 -> 0.08 | U5: =(U4-T4)/T4 -> 0.07 | V5: =(V4-U4)/U4 -> 0.06 | AA5: EBIT | AB5: FY2026E | AC5: FY2027E | AD5: FY2028E | AE5: FY2029E | AF5: FY2030E
A6: Less: taxes | F6: =F5*'Discount rates'!$G$7 -> 997.81295 | G6: =G5*'Discount rates'!$G$7 -> -1935.0147 | H6: =H5*'Discount rates'!$G$7 -> 445.36883 | I6: =I5*'Discount rates'!$G$7 -> 8703.2445 | J6: =J5*'Discount rates'!$G$7 -> 10335.027 | L6: EBIT | M6: =F5 -> 3286.74 | N6: =G5 -> -6373.83 | O6: =H5 -> 1467.02 | P6: =I5 -> 28668 | Q6: =J5 -> 34043 | R6: =Q6*(1+AB$6) -> 36426.01 | S6: =R6*(1+AC$6) -> 38975.831 | T6: =S6*(1+AD$6) -> 42093.897 | U6: =T6*(1+AE$6) -> 45040.47 | V6: =U6*(1+AF$6) -> 48193.303 | AB6: 0.07 | AC6: 0.07 | AD6: 0.08 | AE6: 0.07 | AF6: 0.07
A7: NOPAT | F7: =F5-F6 -> 2288.927 | G7: =G5-G6 -> -4438.8153 | H7: =H5-H6 -> 1021.6512 | I7: =I5-I6 -> 19964.756 | J7: =J5-J6 -> 23707.973 | L7: EBIT Margin | M7: =M6/M4 -> 0.013157763 | N7: =N6/N4 -> -0.022890096 | O7: =O6/O4 -> 0.004240347 | P7: =P6/P4 -> 0.066052864 | Q7: =Q6/Q4 -> 0.077424124 | R7: =AB6 -> 0.07 | S7: =AC6 -> 0.07 | T7: =AD6 -> 0.08 | U7: =AE6 -> 0.07 | V7: =AF6 -> 0.07
A8: Add: Depreciation and amortization | F8: ='Consolidated Income Statement'!C16 -> 23546.71 | G8: ='Consolidated Income Statement'!D16 -> 24835.69 | H8: ='Consolidated Income Statement'!E16 -> 24860.36 | I8: ='Consolidated Income Statement'!F16 -> 27239 | J8: ='Consolidated Income Statement'!G16 -> 23256 | L8: Less: Tax | M8: 997.81295 | N8: -1935.0147 | O8: 445.36883 | P8: 8703.2445 | Q8: 10335.027 | R8: =0.3*R6 -> 10927.803 | S8: =0.3*S6 -> 11692.749 | T8: =0.3*T6 -> 12628.169 | U8: =0.3*U6 -> 13512.141 | V8: =0.3*V6 -> 14457.991 | AA8: TAX | AB8: FY2026E | AC8: FY2027E | AD8: FY2028E | AE8: FY2029E | AF8: FY2030E
A9: Add/Less: Working capital changes | F9: ='Working Capital Schedule'!C37 -> 0 | G9: ='Working Capital Schedule'!D37 -> 5297.63 | H9: ='Working Capital Schedule'!E37 -> 604.25 | I9: ='Working Capital Schedule'!F37 -> 5669.56 | J9: ='Working Capital Schedule'!G37 -> -6983 | L9: NOPAT | M9: =M6-M8 -> 2288.927 | N9: =N6-N8 -> -4438.8153 | O9: =O6-O8 -> 1021.6512 | P9: =P6-P8 -> 19964.756 | Q9: =Q6-Q8 -> 23707.973 | R9: =R6-R8 -> 25498.207 | S9: =S6-S8 -> 27283.081 | T9: =T6-T8 -> 29465.728 | ... V9: =V6-V8 -> 33735.312 | X9: Scenario: | Y9: 1 = Bear | AB9: 0.3 | AC9: 0.3 | AD9: 0.3 | AE9: 0.3 | AF9: 0.3
A10: Less: Investment in fixed assets(CAPEX) | F10: =CAPEX!B33 -> 18147.21 | G10: =CAPEX!C33 -> 21841.92 | H10: =CAPEX!D33 -> 15067.19 | I10: =CAPEX!E33 -> 22960 | J10: =CAPEX!F33 -> 23822 | L10: Add: D&A | M10: 23546.71 | N10: 24835.69 | O10: 24860.36 | P10: 27239 | Q10: 23256 | R10: =R4*AB12 -> 28228.419 | S10: =S4*AC12 -> 35238.476 | T10: =T4*AD12 -> 38057.554 | U10: =U4*AE12 -> 34904.214 | V10: =V4*AF12 -> 30832.056 | Y10: 2 = Base
A11: FCFF | F11: =F7+F8-F9-F10 -> 7688.427 | G11: =G7+G8-G9-G10 -> -6742.6753 | H11: =H7+H8-H9-H10 -> 10210.571 | I11: =I7+I8-I9-I10 -> 18574.196 | J11: =J7+J8-J9-J10 -> 30124.973 | L11: Add/Less: Change in Working Capital | M11: 0 | N11: 5297.63 | O11: 604.25 | P11: 5669.56 | Q11: -6983 | R11: =R4*AB15 -> 4704.7365 | S11: =S4*AC15 -> 5034.0681 | T11: =T4*AD15 -> 5436.7935 | U11: =U4*AE15 -> 5817.369 | V11: =V4*AF15 -> 6166.4112 | Y11: 3 = Bull | AA11: D&A | AB11: FY2026E | AC11: FY2027E | AD11: FY2028E | AE11: FY2029E | AF11: FY2030E
A12: WACC | F12: ='Discount rates'!J37 -> 0.12442103 | L12: Less: CAPEX | M12: =F10 -> 18147.21 | N12: =G10 -> 21841.92 | O12: =H10 -> 15067.19 | P12: =I10 -> 22960 | Q12: =J10 -> 23822 | R12: =R4*AB18 -> 23523.683 | S12: =S4*AC18 -> 25170.34 | T12: =T4*AD18 -> 32620.761 | U12: =U4*AE18 -> 34904.214 | V12: =V4*AF18 -> 36998.467 | AB12: 0.06 | AC12: 0.07 | AD12: 0.07 | AE12: 0.06 | AF12: 0.05
L13: FCFF | M13: =M9+M10-M11-M12 -> 7688.427 | N13: =N9+N10-N11-N12 -> -6742.6753 | O13: =O9+O10-O11-O12 -> 10210.571 | P13: =P9+P10-P11-P12 -> 18574.196 | Q13: =Q9+Q10-Q11-Q12 -> 30124.973 | R13: =R9+R10-R11-R12 -> 25498.207 | S13: =S9+S10-S11-S12 -> 32317.15 | T13: =T9+T10-T11-T12 -> 29465.728 | ... V13: =V9+V10-V11-V12 -> 21402.49
A14: Present value of FCFF | F14: =SUMPRODUCT(R13:V13,R15:V15) -> 96956.071 | L14: Period | R14: 1 | S14: 2 | T14: 3 | U14: 4 | V14: 5 | AA14: WC | AB14: FY2026E | AC14: FY2027E | AD14: FY2028E | AE14: FY2029E | AF14: FY2030E
A15: Terminal value | L15: Discounting Factor | R15: =1/((1+$F$12)^R14) -> 0.88934658 | S15: =1/((1+$F$12)^S14) -> 0.79093735 | T15: =1/((1+$F$12)^T14) -> 0.70341743 | U15: =1/((1+$F$12)^U14) -> 0.62558188 | V15: =1/((1+$F$12)^V14) -> 0.55635911 | AB15: 0.01 | AC15: 0.01 | AD15: 0.01 | AE15: 0.01 | AF15: 0.01
A16: EV/EBITDA | F16: 4 | G16: Moneycontrol | L16: PV of FCFF | R16: =R13*R15 -> 22676.743 | S16: =S13*S15 -> 25560.84 | T16: =T13*T15 -> 20726.707 | U16: =U13*U15 -> 16084.311 | V16: =V13*V15 -> 11907.47
A17: EBITDA | F17: =V6+V10 -> 79025.359 | R17: =SUM(R16:V16) -> 96956.071 | AA17: CAPEX | AB17: FY2026E | AC17: FY2027E | AD17: FY2028E | AE17: FY2029E | AF17: FY2030E
A18: Enterprise value (Terminal value) | F18: =F16*F17 -> 316101.44 | AB18: 0.05 | AC18: 0.05 | AD18: 0.06 | AE18: 0.06 | AF18: 0.06
A19: Present value of terminal value | F19: =F18*V15 -> 175865.91
A21: Enterprise Value | F21: =F14+F19 -> 272821.98
A22: Add: Cash and bank balance | F22: =SUM('Consolidated Balance Sheet'!C23:C24) -> 40834
A23: Value of firm | F23: =SUM(F21:F22) -> 313655.98
A24: Less: Debt | F24: =-'Discount rates'!G29 -> -90599
A25: Value of equity | F25: =SUM(F23:F24) -> 223056.98
A26: Number of shares outstanding (CR) | F26: ='Discount rates'!G25 -> 368.5
A27: Intrinsic value per share | F27: =F25/F26 -> 605.31068 | G27: Unervalued
A28: Market value per share | F28: =INTRO!J22 -> 458.35
A30: Assumptions taken:
A31: 1) Company's enterprise value has been arrived by following Discounting Cashflow Method (DCF).
A32: 2) Discount rate is equivalent to WACC calculated in previous sheet.

Sheet CAPEX
A1: Particulars | B1: FY2021 | C1: FY2022 | D1: FY2023 | E1: FY2024 | F1: FY2025
A2: Gross PPE (Cost) - Opening balance (April 1) | B2: 162571.95 | C2: 179171.53 | D2: 188791.96 | E2: 195678 | F2: 194992
A3: Additions to PPE (Cost) | B3: 8553.95 | C3: 13487.21 | D3: 6448.31 | E3: 8836 | F3: 8786
A4: Additions on account of business/subsidiary acquisition | B4: 0.69 | C4: 0.69 | D4: 627.71 | E4: - | F4: 307
A5: Assets classified as held for sale (Cost) | B5: - | C5: -168.34 | D5: -634.35 | E5: -764 | F5: -91
A6: Disposal/Adjustments (Cost) | B6: -982.41 | C6: -1546.69 | D6: -3204.12 | E6: -13126 | F6: -8607
A7: Currency translation differences (Cost) | B7: 9027.35 | C7: -2151.75 | D7: 3648.82 | E7: 4407 | F7: 7145
A8: Gross PPE (Cost) - Closing balance (March 31) | B8: 179171.53 | C8: 188791.96 | D8: 195678.33 | E8: 194992 | F8: 202108
A9: Accumulated depreciation - Opening balance (April 1) | B9: 84689.12 | C9: 99531.48 | D9: 107891.83 | E9: 121866 | F9: 121866
A10: Depreciation for the year | B10: 10872.96 | C10: 11068.12 | D10: 11798.87 | E10: 13048 | F10: 11203
A11: Reversal of Impairment loss | B11: -530.75 | C11: - | D11: - | E11: - | F11: -
A12: Assets classified as held for sale (Accumulated depreciation) | B12: - | C12: -90.38 | D12: -57.56 | E12: -319 | F12: -6
A13: Disposal/Adjustments (Accumulated depreciation) | B13: -601.87 | C13: -1381.03 | D13: -2864.77 | E13: -12838 | F13: -8154
A14: Provision/(Reversal) for impairment/Write off (Accumulated depreciation) | B14: 63.86 | C14: -35.27 | D14: -58.77 | E14: 81 | F14: -
A15: Currency translation differences (Accumulated depreciation) | B15: 5038.02 | C15: -1201.09 | D15: 2327.3 | E15: 2852 | F15: 4771
A16: Accumulated depreciation - Closing balance (March 31) | B16: 99531.48 | C16: 107891.83 | D16: 119036.9 | E16: 121866 | F16: 129572
A17: Net PPE (Net carrying amount) | B17: 79640.05 | C17: 80900.13 | D17: 76641.43 | E17: 73125 | F17: 72536
A18: Capital Work-in-Progress (CWIP) - Balance at the beginning | B18: 8599.56 | C18: 8377.14 | D18: 3529.04 | E18: 5220 | F18: 10937
A19: CWIP - Additions | B19: 9592.57 | C19: 8354.02 | D19: 7364.73 | E19: 14124 | F19: 14729
A20: CWIP - Additions on account of Ford plant acquisition | B20: - | C20: - | D20: 313.22 | E20: - | F20: -
A21: CWIP - Transferred to cost of Property, plant and equipment | B21: -8114.42 | C21: -13145.37 | D21: -6119.09 | E21: -8582 | F21: -8639
A22: CWIP - (Provision)/Reversal for impairment/(Write off) (Net) | B22: -2229.48 | C22: -72.28 | D22: -0.11 | E22: -1 | F22: -
A23: CWIP - Currency translation impact | B23: 528.91 | C23: 15.53 | D23: 132.08 | E23: 176 | F23: 640
A24: Capital Work-in-Progress (CWIP) - Balance at the end | B24: 8377.14 | C24: 3529.04 | D24: 5219.87 | E24: 10937 | F24: 17624
A27: Capex Calculation
A28: Particulars | B28: FY2021 | C28: FY2022 | D28: FY2023 | E28: FY2024 | F28: FY2025
A29: Additions to PPE | B29: =B3 -> 8553.95 | C29: =C3 -> 13487.21 | D29: =D3 -> 6448.31 | E29: =E3 -> 8836 | F29: =F3 -> 8786
A30: CWIP Additions | B30: =B19 -> 9592.57 | C30: =C19 -> 8354.02 | D30: =D19 -> 7364.73 | E30: =E19 -> 14124 | F30: =F19 -> 14729
A31: Additions on acquisition | B31: =B4 -> 0.69 | C31: =C4 -> 0.69 | D31: =D4 -> 627.71 | E31: 0 | F31: =F4 -> 307
A32: CWIP acquisition additions | B32: 0 | C32: 0 | D32: =D20 -> 313.22 | E32: 0 | F32: 0
A33: Total Investment in Fixed Assets / CAPEX | B33: =SUM(B29:B32) -> 18147.21 | C33: =SUM(C29:C32) -> 21841.92 | D33: 15067.19 | E33: =SUM(E29:E32) -> 22960 | F33: =SUM(F29:F32) -> 23822

Sheet Consolidated Balance Sheet
A1: Particulars | B1: Note | C1: FY2025 | D1: FY2024 | E1: FY2023 | F1: FY2022 | G1: FY2021
A2: I. ASSETS
A3: (1) NON-CURRENT ASSETS
A4: (a) Property, plant and equipment | B4: 3(B)/3(b)/3 | C4: 72536 | D4: 73125 | E4: 76641.43 | F4: 80900.13 | G4: 79640.05
A5: (b) Capital work-in-progress | B5: 3(C)/3(c)/3(b) | C5: 17624 | D5: 10937 | E5: 5219.87 | F5: 3529.04 | G5: 8377.14
A6: (c) Right of use assets | B6: 4 | C6: 8476 | D6: 8059 | E6: 7801.04 | F6: 6686.02 | G6: 6490.66
A7: (d) Goodwill | B7: 5 | C7: 895 | D7: 860 | E7: 840.6 | F7: 807.17 | G7: 803.72
A8: (e) Other intangible assets | B8: 6(B)/6(a) | C8: 33790 | D8: 39241 | E8: 46796.69 | F8: 50462.13 | G8: 51773.18
A9: (f) Intangible assets under development | B9: 6(C)/6(b) | C9: 48182 | D9: 24761 | E9: 9054.63 | F9: 6722.05 | G9: 12586.79
A10: (g) Investment in equity accounted investees | B10: 46273 | C10: 5534 | D10: 5340 | E10: 4675.66 | F10: 4349.39 | G10: 4200.79
A11: (h)(i) Investment/Other investments (non-current) | B11: 46304 | C11: 2923 | D11: 3378 | E11: 2865.19 | F11: 2320.92 | G11: 1368.3
A12: (h)(ii) Finance receivables (non-current) | B12: 17/18 | C12: - | D12: 6095 | E12: 7416.41 | F12: 11135.85 | G12: 16846.82
A13: (h)(iii) Loans / Loans and advances (non-current) | B13: 46367 | C13: 99 | D13: 442 | E13: 870.65 | F13: 843.35 | G13: 1204.59
A14: (h)(iv) Other financial assets (non-current) | B14: 41609 | C14: 12185 | D14: 9085 | E14: 7027.66 | F14: 5179.49 | G14: 5813.98
A15: (i) Deferred tax assets (net) | B15: 22 | C15: 7176 | D15: 13099 | E15: 5184.67 | F15: 3870.85 | G15: 4520.35
A16: (j) Non-current tax assets (net) | C16: 2045 | D16: 2130 | E16: 1556.36 | F16: 1196.79 | G16: 1003.3
A17: (k) Other non-current assets | B17: 19/20 | C17: 6852 | D17: 5720 | E17: 8602.05 | F17: 5639.21 | G17: 1608.49
A18: Total Non-Current Assets | C18: 218317 | D18: 202272 | E18: 184552.91 | F18: 183642.39 | G18: 196238.16
A19: (2) CURRENT ASSETS
A20: (a) Inventories | B20: 13/14 | C20: 47269 | D20: 47788 | E20: 40755.39 | F20: 35240.34 | G20: 36088.59
A21: (b)(i) Investments/Other investments (current) | B21: 46336 | C21: 27199 | D21: 14253 | E21: 18838.31 | F21: 22709.22 | G21: 19051.19
A22: (b)(ii) Trade receivables | B22: 14/15 | C22: 13248 | D22: 16952 | E22: 15737.97 | F22: 12442.12 | G22: 12679.08
A23: (b)(iii) Cash and cash equivalents | B23: 15/16 | C23: 34349 | D23: 40015 | E23: 31886.95 | F23: 38159.01 | G23: 31700.01
A24: (b)(iv) Bank balances other than (iii) above | B24: 16/17 | C24: 6485 | D24: 5792 | E24: 5128.61 | F24: 2510.18 | G24: 15092.45
A25: (b)(v) Finance receivables (current) | B25: 17/18 | C25: - | D25: 24070 | E25: 23417.31 | F25: 22095.35 | G25: 17868.09
A26: (b)(vi) Loans / Loans and advances (current) | B26: 46367 | C26: 72 | D26: 197 | E26: 2302.84 | F26: 1671.93 | G26: 1749.4
A27: (b)(vii) Other financial assets (current) | B27: 41609 | C27: 18984 | D27: 8121 | E27: 2786.72 | F27: 3799.82 | G27: 5274.32
A28: (c) Current tax assets (net) | C28: 411 | D28: 101 | E28: 259.26 | F28: 259.84 | G28: 865.31
A29: (d) Assets classified as held-for-sale | B29: 21/(d) | C29: 514 | D29: 674 | E29: 827.78 | F29: 523.85 | G29: 220.8
A30: (e)/(d) Other current assets | B30: 20/21 | C30: 11794 | D30: 10429 | E30: 9587.33 | F30: 7565.88 | G30: 6298.4
A31: Total Current Assets | C31: 159811 | D31: 167718 | E31: 151528.47 | F31: 146977.54 | G31: 146887.64
A32: TOTAL ASSETS | C32: 378642 | D32: 370664 | E32: 336081.38 | F32: 330619.93 | G32: 343125.8
A33: II. EQUITY AND LIABILITIES
A34: (a) Equity share capital | B34: 23 | C34: 736 | D34: 767 | E34: 766.02 | F34: 765.88 | G34: 765.81
A35: (b) Other equity | B35: 24 | C35: 115408 | D35: 84151 | E35: 44555.77 | F35: 43795.36 | G35: 54480.91
A36: Equity attributable to owners of Tata Motors Limited | C36: 116144 | D36: 84918 | E36: 45321.79 | F36: 44561.24 | G36: 55246.72
A37: Non-controlling interests | C37: 6610 | D37: 8176 | E37: 7277.72 | F37: 4271.06 | G37: 1573.49
A38: Total Equity | C38: 122754 | D38: 93094 | E38: 52599.51 | F38: 48832.3 | G38: 56820.21
A39: (1) NON-CURRENT LIABILITIES
A40: (a)(i) Borrowings (non-current) | B40: 26 | C40: 40217 | D40: 62149 | E40: 88695.81 | F40: 97759.17 | G40: 93112.77
...

Sheet Working Capital Schedule
A1: Particulars | B1: Note | C1: FY2021 | D1: FY2022 | E1: FY2023 | F1: FY2024 | G1: FY2025
A2: Trade receivables - Receivables considered good | B2: 14/15 | C2: 12679.08 | D2: 12442.12 | E2: 15737.97 | F2: 17069 | G2: 13345
A3: Trade receivables - Credit impaired receivables | B3: 14/15 | C3: 989.19 | D3: 851.56 | E3: 821.24 | F3: 634 | G3: 653
A5: Trade receivables - Less: Allowance for receivables considered good | B5: 14/15 | C5: - | D5: - | E5: - | F5: -117 | G5: -97
A6: Trade receivables - Less: Allowance for credit impaired receivables | B6: 14/15 | C6: -989.19 | D6: -851.56 | E6: -821.24 | F6: -634 | G6: -653
A8: Inventories - Raw materials and components | B8: 13/14 | C8: 3029.64 | D8: 4032.42 | E8: 4164.96 | F8: 3401 | G8: 3081
A9: Inventories - Work-in-progress | B9: 13/14 | C9: 4373.48 | D9: 5596.54 | E9: 5840.74 | F9: 6182 | G9: 5942
A10: Inventories - Finished goods | B10: 13/14 | C10: 27313.14 | D10: 23885.39 | E10: 29171.27 | F10: 36622 | G10: 36196
A11: Inventories - Stores and spare parts | B11: 13/14 | C11: 185.33 | D11: 208.02 | E11: 228.91 | F11: 277 | G11: 305
A12: Inventories - Consumable tools | B12: 13/14 | C12: 485.07 | D12: 468.33 | E12: 465.87 | F12: 490 | G12: 614
A13: Inventories - Goods-in-transit-Raw materials and components | B13: 13/14 | C13: 701.93 | D13: 1049.64 | E13: 883.64 | F13: 816 | G13: 1131
A15: Other current assets - Advances and other receivables | B15: 20/21 | C15: 517.55 | D15: 815.21 | E15: 980.59 | F15: 1578 | G15: 1121
A18: Other current assets - Prepaid expenses | B18: 20/21 | C18: 1220.13 | D18: 2029.3 | E18: 2256.78 | F18: 2445 | G18: 2997
A19: Other current assets - Contract assets | B19: 20/21 | C19: - | D19: - | E19: - | F19: 1004 | G19: 1447
A20: Other current assets - Employee benefits | B20: 20/21 | C20: 43.93 | D20: - | E20: - | F20: - | G20: -
A21: Other current assets - Others | B21: 20/21 | C21: 341.61 | D21: 690.09 | E21: 863.47 | F21: 190 | G21: 282
A23: TOTAL Operating Asset | C23: =SUM(C2:C21) -> 50890.89 | D23: =SUM(D2:D21) -> 51217.06 | E23: =SUM(E2:E21) -> 60594.2 | F23: =SUM(F2:F21) -> 69957 | G23: =SUM(G2:G21) -> 66364
A24: Trade payables - Outstanding dues of micro and small enterprises | B24: 30 | C24: 186.21 | D24: 183.92 | E24: 316.01 | F24: 502 | G24: 452
A25: Trade payables - Outstanding dues of creditors other than micro and small enterprises | B25: 30 | C25: 67993.63 | D25: 59786.46 | E25: 71739.76 | F25: 87540 | G25: 93626
A26: Trade payables - Acceptances | C26: 7860.31 | D26: 9779.95 | E26: 7195.99 | F26: 5936 | G26: 3290
A27: Other current liabilities - Contract liabilities | B27: 32/33 | C27: 5735.93 | D27: 6558.65 | E27: 6283.85 | F27: - | G27: -
A28: Other current liabilities - Government grants | B28: 32/33 | C28: 750.34 | D28: 946.92 | E28: 812.07 | F28: - | G28: -
A29: Other current liabilities - Statutory dues | B29: 32/33 | C29: 3729.69 | D29: 4143.75 | E29: 3804.17 | F29: - | G29: -
A30: Other current liabilities - Others | B30: 32/33 | C30: 227.22 | D30: 112.22 | E30: 132.91 | F30: - | G30: -
A33: TOTAL operating Liabilities | C33: =SUM(C24:C30) -> 86483.33 | D33: =SUM(D24:D30) -> 81511.87 | E33: =SUM(E24:E30) -> 90284.76 | F33: =SUM(F24:F30) -> 93978 | G33: =SUM(G24:G30) -> 97368
A36: NET WORKING CAPTIAL | C36: =C23-C33 -> -35592.44 | D36: =D23-D33 -> -30294.81 | E36: =E23-E33 -> -29690.56 | F36: =F23-F33 -> -24021 | G36: =G23-G33 -> -31004
A37: Change in Net working Capital | D37: =D36-C36 -> 5297.63 | E37: =E36-D36 -> 604.25 | F37: =F36-E36 -> 5669.56 | G37: =G36-F36 -> -6983

Sheet Debt Schedule
A1: DEBT SCHEDULE
A3: Particulars | B3: FY2025 | C3: FY2024 | D3: FY2023 | E3: FY2022 | F3: FY2021 | H3: FY2025 | I3: FY2024 | J3: FY2023 | K3: FY2022 | L3: FY2021
A5: Long-term Borrowings - Secured - Term loans from banks | B5: - | C5: 12980 | D5: - | E5: - | F5: -
A6: Long-term Borrowings - Secured - Others | B6: 334 | C6: 306 | D6: 275.86 | E6: 250.73 | F6: 226.11 | H6: 40217 | I6: 62149 | J6: 88695.81 | K6: 97759.17 | L6: 93112.77
A7: Long-term Borrowings - Secured - Privately placed Non-Convertible Debentures | B7: - | C7: - | D7: - | E7: 1994.68 | F7: 2769.58 | H7: 22282 | I7: 36352 | J7: 36964.66 | K7: 41917.87 | L7: 42791.74
A8: Long-term Borrowings - Secured - Collateralized debt obligations | B8: - | C8: - | D8: - | E8: 332.33 | F8: 1260.87 | H8: 7642 | I8: 7670 | J8: 7568.49 | K8: 5962.44 | L8: 5412.06
A9: Long-term Borrowings - Secured - Term loans from financial institutions | B9: - | C9: - | D9: - | E9: 1345.1 | F9: 2992.85 | H9: 1399 | I9: 1093 | J9: 884.48 | K9: 809.55 | L9: 814
A10: Long-term Borrowings - Unsecured - Privately placed Non-Convertible Debentures | B10: 3739 | C10: 3574 | D10: 7689.05 | E10: 7884.83 | F10: 5151.85 | H10: =SUM(H6:H9) -> 71540 | I10: =SUM(I6:I9) -> 107264 | J10: =SUM(J6:J9) -> 134113.44 | K10: =SUM(K6:K9) -> 146449.03 | L10: =SUM(L6:L9) -> 142130.57
A11: Long-term Borrowings - Unsecured - Perpetual Debentures | B11: 1282 | C11: 1770 | D11: 1744.09 | E11: 1718.2 | F11: 1320.15
A12: Long-term Borrowings - Unsecured - Term loans from banks | B12: 11180 | C12: 8938 | D12: 21585.29 | E12: 22790.25 | F12: 20468.26
A13: Long-term Borrowings - Unsecured - Term loans from other parties | B13: 413 | C13: 383 | D13: 360.81 | E13: - | F13: 168.19
A14: Long-term Borrowings - Unsecured - Senior notes | B14: 23269 | C14: 34198 | D14: 46152.39 | E14: 49873.48 | F14: 46642.21
A15: Long-term Borrowings - Unsecured - Others | B15: - | C15: - | D15: 10.82 | E15: 355.72 | F15: 10.81
A17: Current maturities of long-term borrowings - Secured - Privately placed Non-Convertible Debentures | B17: - | C17: - | D17: 1998.77 | E17: 778.55 | F17: 681.25
A18: Current maturities of long-term borrowings - Secured - Term loans from banks | B18: 953 | C18: 7683 | D18: 7937.42 | E18: 5910.53 | F18: 5195.05
A19: Current maturities of long-term borrowings - Secured - Term loans from other financial institutions | B19: - | C19: - | D19: - | E19: 1050 | F19: 1117.49
A20: Current maturities of long-term borrowings - Secured - Others | B20: 18 | C20: - | D20: - | E20: - | F20: -
A21: Current maturities of long-term borrowings - Unsecured - Privately placed Non-Convertible Debentures | B21: 875 | C21: 4307 | D21: 1629.42 | E21: 2454.57 | F21: 3816.98
A22: Current maturities of long-term borrowings - Unsecured - Collateralised debt obligation | B22: - | C22: - | D22: 74.87 | E22: 850.21 | F22: 1712.78
A23: Current maturities of long-term borrowings - Unsecured - Senior Notes | B23: 11890 | C23: 8136 | D23: 6794.73 | E23: 7748.41 | F23: 6216.03
A24: Current maturities of long-term borrowings - Unsecured - Term loans from banks and others | B24: 2859 | C24: 10491 | D24: 4462.62 | E24: 5747.22 | F24: 2063.37
A25: Current maturities of long-term borrowings - Unsecured - Others | B25: - | C25: - | D25: - | E25: - | F25: 326
A27: Short-term Borrowings - Secured - Loans from banks | B27: 1620 | C27: 2914 | D27: 2293.93 | E27: 4801.28 | F27: 6298.57
A28: Short-term Borrowings - Secured - Current maturities of long-term borrowings | B28: 971 | C28: 7683 | D28: 9936.19 | E28: 7739.08 | F28: 6993.79
A29: Short-term Borrowings - Unsecured - Loans from banks | B29: 4067 | C29: 760 | D29: 6878.29 | E29: 6478.92 | F29: 7019.31
A30: Short-term Borrowings - Unsecured - Inter corporate deposits from associates | B30: - | C30: 92 | D30: 48 | E30: 241 | F30: 95
A31: Short-term Borrowings - Unsecured - Commercial paper | B31: - | C31: 1969 | D31: 4846.62 | E31: 5857.18 | F31: 8249.91
A32: Short-term Borrowings - Unsecured - Current maturities of long-term borrowings | B32: 15624 | C32: 22934 | D32: 12961.63 | E32: 16800.41 | F32: 14135.16
A33: TOTAL GROSS DEBT | B33: =SUM(B5:B32) -> 79094 | C33: =SUM(C5:C32) -> 129118 | D33: =SUM(D5:D32) -> 137680.8 | E33: =SUM(E5:E32) -> 153002.68 | F33: =SUM(F5:F32) -> 144931.57
A35: Lease liabilities - Non-current | B35: 7642 | C35: 7670 | D35: 7568.49 | E35: 5962.44 | F35: 5412.06
A36: Lease liabilities - Current | B36: 1399 | C36: 1093 | D36: 884.48 | E36: 809.55 | F36: 814
A37: Compulsorily Convertible Preference Shares - liability portion (Non-current) | B37: 2464 | C37: 2548 | D37: - | E37: - | F37: -
A38: TOTAL NET DEBT | B38: =SUM(B33:B37) -> 90599 | C38: =SUM(C33:C37) -> 140429 | D38: =SUM(D33:D37) -> 146133.77 | E38: =SUM(E33:E37) -> 159774.67 | F38: =SUM(F33:F37) -> 151157.63

Sheet Consolidated cash flow
A1: Particulars | B1: FY2025 | C1: FY2024 | D1: FY2023 | E1: FY2022 | F1: FY2021
A2: Profit/(Loss) for the year | B2: 23,278 (continuing) | C2: 32,453 (continuing) | D2: 2689.87 | E2: -11308.76 | F2: -13395.1
A3: Profit/(loss) for the year from discontinued operation | B3: 4871 | C3: -646 | D3: - | E3: - | F3: -
A4: Depreciation and amortisation expense | B4: 23256 | C4: 27270 | D4: 24860.36 | E4: 24835.69 | F4: 23546.71
A5: Allowances for finance receivables | B5: - | C5: 1153 | D5: 2039.15 | E5: 1307.59 | F5: 957.93
A6: Allowances/(reversal) for trade and other receivables | B6: 109 | C6: 197 | D6: 80.63 | E6: 151.26 | F6: 50.01
A7: Inventory write-down (net) | B7: 337 | C7: 1334 | D7: 723.21 | E7: 125.34 | F7: 129.19
A8: Discounting of warranty and other provisions | B8: 80 | C8: -107 | D8: -140.76 | E8: - | F8: -
A9: Reversal for costs of closure of operations of a subsidiary company | B9: - | C9: - | D9: - | E9: -3.32 | F9: -51.99
A10: Write off/provision (reversal) for tangible/intangible assets (net) | B10: - | C10: - | D10: 229.95 | E10: - | F10: 114
A11: Restructuring cost at JLR / Charge associated with change in JLR Strategy | B11: - | C11: - | D11: - | E11: - | F11: 14994.3
A12: Reversal of Impairment in subsidiaries | B12: - | C12: - | D12: -214.39 | E12: -104.42 | F12: -
A13: Impairment in subsidiaries | B13: - | C13: - | D13: - | E13: - | F13: 353.2
A14: Impairment losses/(Reversal) in Passenger Vehicle Business | B14: - | C14: - | D14: - | E14: - | F14: -1182.41
A15: Reversal for onerous contracts and related supplier claims | B15: - | C15: - | D15: -61.03 | E15: - | F15: -663
A16: Other exceptional items / Defined benefit pension plan amendment past service cost/(credit) | B16: - | C16: - | D16: (1,495.07)/(61.99) | E16: - | F16: 84.81
A17: Employee separation cost | B17: - | C17: - | D17: - | E17: - | F17: 430.76
A18: Fair value adjustments in relation to asset held for sale | B18: - | C18: 58 | D18: - | E18: - | F18: -
A19: Non cash exceptional items | B19: 492 | C19: 977 | D19: - | E19: - | F19: -
A20: Gain on Disposal due to merger of Tata Motors Finance Ltd with Tata Capital Ltd | B20: -4975 | C20: - | D20: - | E20: - | F20: -
A21: Accrual for share-based payments | B21: 48 | C21: 43 | D21: 30.03 | E21: 18.05 | F21: 9.04
A22: Lease charges (Amortisation considered as employee cost) | B22: 121 | C22: - | D22: - | E22: - | F22: -
A23: Marked-to-market gain on investments measured at fair value through profit or loss | B23: -8 | C23: -24 | D23: -93.27 | E23: - | F23: -19.91
A24: Loss on sale of assets (including assets scrapped/written off) (net) | B24: 232 | C24: 303 | D24: 354.96 | E24: 94.19 | F24: 265.59
A25: Profit on sale of investments (net) | B25: -224 | C25: -263 | D25: -303.44 | E25: -266.56 | F25: -177.26
A26: Share of (profit)/loss of joint ventures and associates / equity accounted investees (net) | B26: -287 | C26: -700 | D26: -336.38 | E26: 74.06 | F26: 378.96
A27: Tax expense/(credit) (net) (including discontinued operation) | B27: 10606 | C27: -3852 | D27: 704.06 | E27: 4231.29 | F27: 2541.86
A28: Finance costs (and Compulsorily convertible preference share measured at Fair Value) | B28: 5083 | C28: 9986 | D28: 10239.23 | E28: 9326.31 | F28: 8097.17
A29: Compulsorily convertible preference share measured at fair value (gain)/loss | B29: -84 | C29: 48 | D29: - | E29: - | F29: -
A30: Interest income | B30: -2473 | C30: -2608 | D30: -1251.18 | E30: -625.22 | F30: -492.53
A31: Dividend income | B31: -64 | C31: -47 | D31: -46.42 | E31: -34.22 | F31: -18.37
A32: Other non cash item | B32: -77 | C32: 68 | D32: - | E32: - | F32: -
A33: Gain on fair value of below market interest loans | B33: -40 | C33: - | D33: - | E33: - | F33: -
A34: Unrealised/Foreign exchange (gain)/loss (net) | B34: -1344 | C34: -537 | D34: 3746.61 | E34: -878.51 | F34: -4402.12
A35: Cash flows from operating activities before changes in following assets and liabilities | B35: 58937 | C35: 65106 | D35: 41694.13 | E35: 26,942.77 / 26,666.17 | F35: 31197.64
A36: Finance receivables | B36: - | C36: -725 | D36: 617.45 | E36: -75.63 | F36: -4386.94
A37: Trade receivables | B37: 3573 | C37: -1151 | D37: -2830.1 | E37: 412.34 / 261.08 | F37: -1118.35
A38: Loans and other financial assets / Loans and advances and other financial assets | B38: -3289 | C38: -3083 | D38: -736.04 | E38: 129.26 | F38: -1308.92
A39: Other current and non-current assets | B39: -3183 | C39: 1666 | D39: -3182.09 | E39: -5312.17 | F39: 3853.53
A40: Inventories | B40: 2127 | C40: -7265 | D40: -5665.36 | E40: 597.40 / 472.06 | F40: 3814.5
...

Sheet Fixed asset Schedule
A1: Particulars | B1: FY2025 | C1: FY2024 | D1: FY2023 | E1: FY2022 | F1: FY2021 | J1: Asset Class | K1: Line Item | L1: FY2025 | M1: FY2024 | N1: FY2023 | O1: FY2022 | P1: FY2021
A2: Gross PPE (Cost) - Opening balance (April 1) | B2: 194992 | C2: 195678 | D2: 188791.96 | E2: 179171.53 | F2: 162571.95 | J2: Land | K2: Cost - Opening | L2: 7640 | M2: 7757 | N2: 7457 | O2: 7513.05 | P2: 7,456.81 (FY22 opening not in FY21 report)
A3: Additions to PPE (Cost) | B3: 8786 | C3: 8836 | D3: 6448.31 | E3: 13487.21 | F3: 8553.95 | J3: Land | K3: Cost - Additions | L3: -16 | M3: - | N3: - | O3: 12.26 | P3: -
A4: Additions on account of business/subsidiary acquisition | B4: 307 | C4: - | D4: 627.71 | E4: 0.69 | F4: 0.69 | J4: Land | K4: Cost - Disposals/Adjustments/Held for sale | L4: -216 | M4: -127 | N4: -96 | O4: -21.19 | P4: -
A5: Assets classified as held for sale (Cost) | B5: -91 | C5: -764 | D5: -634.35 | E5: -168.34 | F5: - | J5: Land | K5: Cost - Currency translation | L5: 102 | M5: 70 | N5: 64 | O5: -47.31 | P5: -
A6: Disposal/Adjustments (Cost) | B6: -8607 | C6: -13126 | D6: -3204.12 | E6: -1546.69 | F6: -982.41 | J6: Land | K6: Cost - Closing | L6: 7510 | M6: 7641 | N6: 7757 | O6: 7456.81 | P6: 7,456.81 (matches FY22 report)
A7: Currency translation differences (Cost) | B7: 7145 | C7: 4407 | D7: 3648.82 | E7: -2151.75 | F7: 9027.35 | J7: Land | K7: Accumulated depreciation - Closing | L7: - | M7: 72 | N7: - | O7: - | P7: -
A8: Gross PPE (Cost) - Closing balance (March 31) | B8: 202108 | C8: 194992 | D8: 195678.33 | E8: 188791.96 | F8: 179171.53 | J8: Land | K8: Net carrying amount | L8: 7510 | M8: 7569 | N8: 7757 | O8: 7456.81 | P8: -
A9: Accumulated depreciation - Opening balance (April 1) | B9: 121866 | C9: 121866 | D9: 107891.83 | E9: 99531.48 | F9: 84689.12 | J9: Buildings | K9: Cost - Opening | L9: 30832 | M9: 29571 | N9: 28644 | O9: 28534.98 | P9: -
A10: Depreciation for the year | B10: 11203 | C10: 13048 | D10: 11798.87 | E10: 11068.12 | F10: 10872.96 | J10: Buildings | K10: Cost - Additions | L10: 2388 | M10: 1138 | N10: 721 | O10: 599.05 | P10: -
A11: Reversal of Impairment loss | B11: - | C11: - | D11: - | E11: - | F11: -530.75 | J11: Buildings | K11: Cost - Disposals/Adjustments/Held for sale/Impairment | L11: -231 | M11: -551 | N11: -139 | O11: -139.1 | P11: -
A12: Assets classified as held for sale (Accumulated depreciation) | B12: -6 | C12: -319 | D12: -57.56 | E12: -90.38 | F12: - | J12: Buildings | K12: Cost - Currency translation | L12: 1254 | M12: 674 | N12: 697 | O12: -350.85 | P12: -
A13: Disposal/Adjustments (Accumulated depreciation) | B13: -8154 | C13: -12838 | D13: -2864.77 | E13: -1381.03 | F13: -601.87 | J13: Buildings | K13: Cost - Closing | L13: 34251 | M13: 30832 | N13: 29571 | O13: 28644.08 | P13: -
A14: Provision/(Reversal) for impairment/Write off (Accumulated depreciation) | B14: - | C14: 81 | D14: -58.77 | E14: -35.27 | F14: 63.86 | J14: Buildings | K14: Accumulated depreciation - Opening | L14: 11028 | M14: 9562 | N14: 8111 | O14: 6992.5 | P14: -
A15: Currency translation differences (Accumulated depreciation) | B15: 4771 | C15: 2852 | D15: 2327.3 | E15: -1201.09 | F15: 5038.02 | J15: Buildings | K15: Depreciation for the year | L15: 1532 | M15: 1468 | N15: 1300 | O15: 1306.19 | P15: -
A16: Accumulated depreciation - Closing balance (March 31) | B16: 129572 | C16: 121866 | D16: 119036.9 | E16: 107891.83 | F16: 99531.48 | J16: Buildings | K16: Accumulated depreciation - Adjustments | L16: -122 | M16: -230 | N16: -52 | O16: -80.01 | P16: -
A17: Net PPE (Net carrying amount) | B17: 72536 | C17: 73125 | D17: 76641.43 | E17: 80900.13 | F17: 79640.05 | J17: Buildings | K17: Currency translation (accum. dep.) | L17: 448 | M17: 220 | N17: 242 | O17: -107.44 | P17: -
A18: Capital Work-in-Progress (CWIP) - Balance at the beginning | B18: 10937 | C18: 5220 | D18: 3529.04 | E18: 8377.14 | F18: 8599.56 | J18: Buildings | K18: Accumulated depreciation - Closing | L18: 12875 | M18: 11028 | N18: 9562 | O18: 8111.24 | P18: -
A19: CWIP - Additions | B19: 14729 | C19: 14124 | D19: 7364.73 | E19: 8354.02 | F19: 9592.57 | J19: Buildings | K19: Net carrying amount | L19: 21376 | M19: 19804 | N19: 20009 | O19: 20532.84 | P19: -
A20: CWIP - Additions on account of Ford plant acquisition | B20: - | C20: - | D20: 313.22 | E20: - | F20: - | J20: Plant and equipment | K20: Cost - Opening | L20: 150271 | M20: 152207 | N20: 147025 | O20: 137463.16 | P20: -
A21: CWIP - Transferred to cost of Property, plant and equipment | B21: -8639 | C21: -8582 | D21: -6119.09 | E21: -13145.37 | F21: -8114.42 | J21: Plant and equipment | K21: Cost - Additions | L21: 6046 | M21: 7222 | N21: 5266 | O21: 12467.83 | P21: -
A22: CWIP - (Provision)/Reversal for impairment/(Write off) (Net) | B22: - | C22: -1 | D22: -0.11 | E22: -72.28 | F22: -2229.48 | J22: Plant and equipment | K22: Cost - Disposals/Adjustments | L22: -8289 | M22: -12703 | N22: -2875 | O22: -1230.33 | P22: -
A23: CWIP - Currency translation impact | B23: 640 | C23: 176 | D23: 132.08 | E23: 15.53 | F23: 528.91 | J23: Plant and equipment | K23: Cost - Currency translation | L23: 5595 | M23: 3545 | N23: 2781 | O23: -1675.75 | P23: -
A24: Capital Work-in-Progress (CWIP) - Balance at the end | B24: 17624 | C24: 10937 | D24: 5219.87 | E24: 3529.04 | F24: 8377.14 | J24: Plant and equipment | K24: Cost - Closing | L24: 153944 | M24: 150271 | N24: 152207 | O24: 147024.91 | P24: -
J25: Plant and equipment | K25: Accumulated depreciation - Opening | L25: 106647 | M25: 105420 | N25: 96074 | O25: 89067.35 | P25: -
J26: Plant and equipment | K26: Depreciation for the year | L26: 9227 | M26: 11127 | N26: 10115 | O26: 9354.53 | P26: -
J27: Plant and equipment | K27: Accumulated depreciation - Disposals/Adjustments | L27: -7730 | M27: -12450 | N27: -2706 | O27: -1200.32 | P27: -
J28: Plant and equipment | K28: Currency translation (accum. dep.) | L28: 4177 | M28: 2549 | N28: 1996 | O28: -1120.95 | P28: -
J29: Plant and equipment | K29: Accumulated depreciation - Closing | L29: 112321 | M29: 106646 | N29: 105420 | O29: 96074.21 | P29: -
J30: Plant and equipment | K30: Net carrying amount | L30: 41623 | M30: 43625 | N30: 46787 | O30: 50950.7 | P30: -
J31: Vehicles (owned) | K31: Cost - Opening | L31: 1890 | M31: 1909 | N31: 1816 | O31: 1814.99 | P31: -
J32: Vehicles (owned) | K32: Cost - Additions | L32: 81 | M32: 63 | N32: 73 | O32: 121.1 | P32: -
J33: Vehicles (owned) | K33: Cost - Disposals/Adjustments | L33: -150 | M33: -160 | N33: -19 | O33: -74.5 | P33: -
J34: Vehicles (owned) | K34: Cost - Currency translation | L34: 70 | M34: 42 | N34: 40 | O34: -45.89 | P34: -
J35: Vehicles (owned) | K35: Cost - Closing | L35: 1891 | M35: 1856 | N35: 1909 | O35: 1815.7 | P35: -
J36: Vehicles (owned) | K36: Net carrying amount | L36: 516 | M36: 527 | N36: 568 | O36: 580.19 | P36: -
... J46: Given on lease - Plant and equipment | K46: Net carrying amount | L46: 1 | M46: 1 | N46: 2 | O46: 1.04 | P46: -
J47: TOTAL PPE | K47: Cost - Opening | L47: 194992 | M47: 195678 | N47: 188792 | O47: 179171.53 | P47: 162571.95
J48: TOTAL PPE | K48: Cost - Additions (net of reclass/acquisitions) | L48: 8,786 (+22 reclass +307 acquisition) | M48: 8835 | N48: 6448 | O48: 13487.21 | P48: 8553.95
J49: TOTAL PPE | K49: Cost - Disposal/Adjustments/Held for sale | L49: -9144 | M49: -13918 | N49: -3838 | O49: -1715.03 | P49: -982.41
...

Sheet Discount rates
A1: DISCOUNT RATE CALCULATION
A3: Risk free rate | G3: 0.06477
O4: COST OF DEBT CALCULATION
A5: Cost of debt | O5: Finance costs (and Compulsorily convertible preference share measured at Fair Value) | P5: ='Consolidated cash flow'!B28 -> 5083 | Q5: ='Consolidated cash flow'!C28 -> 9986 | R5: ='Consolidated cash flow'!D28 -> 10239.23 | S5: ='Consolidated cash flow'!E28 -> 9326.31 | T5: ='Consolidated cash flow'!F28 -> 8097.17
A6: Interest rate (Pre-tax) | G6: =AVERAGE(P9:S9) -> 0.064184746 | H6: Calculated | O6: TOTAL GROSS DEBT | P6: ='Debt Schedule'!B33 -> 79094 | Q6: ='Debt Schedule'!C33 -> 129118 | R6: ='Debt Schedule'!D33 -> 137680.8 | S6: ='Debt Schedule'!E33 -> 153002.68 | T6: ='Debt Schedule'!F33 -> 144931.57
A7: Tax rate | G7: =P15 -> 0.30358743 | H7: Calculated | O7: AVG DEBT | P7: =(P6+Q6)/2 -> 104106 | Q7: =(Q6+R6)/2 -> 133399.4 | R7: =(R6+S6)/2 -> 145341.74 | S7: =(S6+T6)/2 -> 148967.12
A8: Post tax cost of debt | G8: =G6*(1-G7) -> 0.044699064 | H8: Calculated
O9: INT RATE | P9: =P5/P7 -> 0.048825236 | Q9: =Q5/Q7 -> 0.074857908 | R9: =R5/R7 -> 0.070449342 | S9: =S5/S7 -> 0.062606498
A10: Cost of equity
A11: Risk free rate | G11: =G3 -> 0.06477 | H11: Calculated | O11: Tax rate calulation
A12: Beta | G12: =SLOPE(C37:C207,E37:E207) -> 1.8543162 | H12: Calculated | O12: Particulars | P12: FY2025 | Q12: FY2024 | R12: FY2023 | S12: FY2022 | T12: FY2021
A13: Return of markets | G13: 0.12 | H13: Assumed | O13: Profit Before Tax (Continuing Operations) | P13: ='Consolidated Income Statement'!G38 -> 34593 | Q13: ='Consolidated Income Statement'!F38 -> 29607 | R13: ='Consolidated Income Statement'!E38 -> 3057.55 | S13: ='Consolidated Income Statement'!D38 -> -7003.41 | T13: ='Consolidated Income Statement'!C38 -> -10474.28
A14: Risk free rate | G14: =G3 -> 0.06477 | H14: Calculated | O14: Total Tax Expense/(Credit) | P14: ='Consolidated Income Statement'!G42 -> 10502 | Q14: ='Consolidated Income Statement'!F42 -> -4024 | R14: ='Consolidated Income Statement'!E42 -> 704.06 | S14: ='Consolidated Income Statement'!D42 -> 4231.29 | T14: ='Consolidated Income Statement'!C42 -> 2541.86
G15: =G11+(G12*(G13-G14)) -> 0.16718388 | H15: Calculated | O15: Effective Tax Rate | P15: =P14/P13 -> 0.30358743 | Q15: 0 | R15: 0 | S15: 0 | T15: 0
A17: Start date
A18: Start date | E18: 45987 | G18: 26215.55 | H18: Calculated
A19: Valuation date | E19: 46240 | G19: =D37 -> 24636 | H19: Calculated
A20: Years | E20: =YEARFRAC(E18,E19,1) -> 0.69315068
A21: CAGR | G21: 0.12 | H21: Assumed
A24: Calculation of market value weights
A25: Shares outstanding | G25: 368.5
A26: Price per share (Rs.) | G26: =INTRO!J22 -> 458.35
A27: Value of equity shares (in CR) | G27: =G26*G25 -> 168901.98
A29: Value of debt | G29: ='Debt Schedule'!B38 -> 90599
A32: Calculation of beta
G34: WACC Calculation
A35: Date | B35: Close | C35: Return of Stock | D35: NIFTY 50 | E35: Return of NIFTY | G35: Kd | H35: =G8 -> 0.044699064 | I35: Wd | J35: =G29/SUM(G27,G29) -> 0.34912778
G36: Ke | H36: =G15 -> 0.16718388 | I36: We | J36: =G27/SUM(G27,G29) -> 0.65087222
A37: 46240 | B37: 459.65 | C37: =B37/B38-1 -> 0.020990671 | D37: 24636 | E37: =D37/D38-1 -> 0.00046092026 | G37: WACC | J37: =SUMPRODUCT(J35:J36,H35:H36) -> 0.12442103
A38: 46239 | B38: 450.2 | C38: =B38/B39-1 -> 0.0077224398 | D38: 24624.65 | E38: =D38/D39-1 -> 0.00039610155
A39: 46238 | B39: 446.75 | C39: =B39/B40-1 -> -0.012707182 | D39: 24614.9 | E39: =D39/D40-1 -> -0.0064340869
A40: 46237 | B40: 452.5 | C40: =B40/B41-1 -> 0.035943223 | D40: 24774.3 | E40: =D40/D41-1 -> 0.016023065
A41: 46234 | B41: 436.8 | C41: =B41/B42-1 -> 0.052656947 | D41: 24383.6 | E41: =D41/D42-1 -> 0.0027326393
A42: 46233 | B42: 414.95 | C42: =B42/B43-1 -> 0.0086290715 | D42: 24317.15 | E42: =D42/D43-1 -> 0.002760802
A43: 46232 | B43: 411.4 | C43: =B43/B44-1 -> -0.012718982 | D43: 24250.2 | E43: =D43/D44-1 -> 0.011042157
A44: 46231 | B44: 416.7 | C44: =B44/B45-1 -> 0.01362199 | D44: 23985.35 | E44: =D44/D45-1 -> -0.00044174121
A45: 46230 | B45: 411.1 | C45: =B45/B46-1 -> 0.012187615 | D45: 23995.95 | E45: =D45/D46-1 -> 0.0096139889
A46: 46227 | B46: 406.15 | C46: =B46/B47-1 -> -0.0042902672 | D46: 23767.45 | E46: =D46/D47-1 -> -0.004279502
A47: 46226 | B47: 407.9 | C47: =B47/B48-1 -> 0.0060426686 | D47: 23869.6 | E47: =D47/D48-1 -> -0.005277908
A48: 46225 | B48: 405.45 | C48: =B48/B49-1 -> -0.015300546 | D48: 23996.25 | E48: =D48/D49-1 -> -0.00791518
...
